Workbook

Sheet README
A1: Chatbot interaction dataset
A2: Built 2026-09-09 15:39 from the structuredcreativeplanning RTDB export.
A4: Sheets
A5: Sessions one row per chat session, with process metrics
A6: Turns one row per message. visible_text has HTML stripped and
A7: control payloads unwrapped; word_count follows visible_text,
A8: not the raw field, so it differs from the CSV export.
A9: Ideas SCAMPER ideas the bot logged, with the bot's OWN ratings of
A10: originality / elaboration / flexibility. These are the model's
A11: judgements, not ground truth - treat as a variable to validate
A12: against your human coding, never as the criterion measure.
A13: Bot_Actions stage switches and story-graph writes
... A43: Counts
A44: Sessions | B44: =COUNTA(Sessions!B2:B88)
A45: Turns | B45: =COUNTA(Turns!C2:C100000)
A46: Student turns | B46: =SUM(Sessions!H2:H88)
A47: Bot turns | B47: =SUM(Sessions!I2:I88)
A48: Distinct participants | B48: =SUMPRODUCT((Sessions!A2:A88<>"")/COUNTIF(Sessions!A2:A88,Sessions!A2:A88&""))
A49: Ideas logged | B49: =COUNTA(Ideas!A2:A100000)
A50: Sessions with a control payload | B50: =COUNTIF(Sessions!S2:S88,">0")
A51: Sessions with zero turns | B51: =COUNTIF(Sessions!G2:G88,0)
A52: Total student words | B52: =SUM(Sessions!J2:J88)
A53: Total bot words | B53: =SUM(Sessions!K2:K88)
A54: Mean student:bot word ratio | B54: =IFERROR(AVERAGE(Sessions!L2:L88),"")

Sheet Sessions
A1: uid | B1: session_id | C1: title | D1: created | E1: updated | F1: mode | G1: n_turns | H1: n_student_turns | I1: n_bot_turns | J1: student_words | K1: bot_words | L1: student_bot_ratio | M1: mean_student_turn_words | N1: duration_min | O1: n_dontknow_turns | P1: modes_used | Q1: stages_used | R1: scamper_techniques | S1: n_control_payloads | T1: n_ideas_logged | U1: has_story | V1: story_words | W1: csv_student_words
A2: 04E9XYnVi8QD3yHAIXeBHCRp2sN2 | B2: -OwQi7O4WPmWWyungHqQ | C2: New Chat | D2: 2026-07-01 11:28:27 | E2: 2026-07-01 11:28:27 | F2: brainstorming | G2: 0 | H2: 0 | I2: 0 | J2: 0 | K2: 0 | O2: 0 | S2: 0 | T2: 0 | U2: no | V2: 0 | W2: 0
A3: 0QaQYslhRSXNMdCEaDY35HzA2Xl2 | B3: -OwWRuDalQgU7vQhUj5g | C3: Creepy House Hidden Secret Found | D3: 2026-07-02 14:11:08 | E3: 2026-07-02 14:16:42 | F3: brainstorming | G3: 14 | H3: 7 | I3: 7 | J3: 54 | K3: 269 | L3: 0.201 | M3: 7.7 | N3: 5.7 | O3: 3 | P3: brainstorming:14 | Q3: Clarify:14 | R3: Substitute:1 | S3: 2 | T3: 1 | U3: yes | V3: 125 | W3: 54
A4: 0QaQYslhRSXNMdCEaDY35HzA2Xl2 | B4: -OwWTu17Sxd9ROSqJ5t4 | C4: Alien Pet and Hidden Trapdoor | D4: 2026-07-02 14:19:51 | E4: 2026-07-02 14:30:05 | F4: brainstorming | G4: 42 | H4: 21 | I4: 21 | J4: 367 | K4: 977 | L4: 0.376 | M4: 17.5 | N4: 30.5 | O4: 6 | P4: brainstorming:30; deepthinking:12 | Q4: Clarify:30 | S4: 2 | T4: 0 | U4: yes | V4: 125 | W4: 367
A5: 3Oh8HB9tTRgaFMqElgVenKJCKCe2 | B5: -OwWR_fPwmqt12YqfVXq | C5: Brainstorming Lost Field Trip Emotions | D5: 2026-07-02 14:09:29 | E5: 2026-07-02 14:18:24 | F5: brainstorming | G5: 56 | H5: 28 | I5: 28 | J5: 627 | K5: 1703 | L5: 0.368 | M5: 22.4 | N5: 43.3 | O5: 0 | P5: brainstorming:56 | Q5: Clarify:56 | S5: 0 | T5: 0 | U5: yes | V5: 221 | W5: 627
A6: 3w9E9Xr7oehGE2ThwcIxvybuKwE2 | B6: -OwVprk7ZBkimJoUaB_0 | C6: Lost Dog Finds Home by Scent | D6: 2026-07-02 11:20:34 | E6: 2026-07-02 11:24:45 | F6: brainstorming | G6: 24 | H6: 12 | I6: 12 | J6: 139 | K6: 482 | L6: 0.288 | M6: 11.6 | N6: 12.3 | O6: 0 | P6: brainstorming:24 | Q6: Clarify:24 | R6: Modify:1; Eliminate:1 | S6: 2 | T6: 2 | U6: yes | V6: 217 | W6: 139
A7: 4J7XUz8OJaZ7l0X9s0VrHR2DYNs2 | B7: -OwQ5lp6LdgjuthVXkK4 | C7: New Chat | D7: 2026-07-01 08:36:29 | E7: 2026-07-01 08:36:29 | F7: brainstorming | G7: 0 | H7: 0 | I7: 0 | J7: 0 | K7: 0 | O7: 0 | S7: 0 | T7: 0 | U7: yes | V7: 1730 | W7: 0
A8: 5iy5k09B1rhCSEHuf17zeB2lmXL2 | B8: -OwWRTKbVRiZWmp90Opw | C8: The Best Mistake Ever | D8: 2026-07-02 14:09:00 | E8: 2026-07-02 14:14:35 | F8: brainstorming | G8: 54 | H8: 27 | I8: 27 | J8: 291 | K8: 993 | L8: 0.293 | M8: 10.8 | N8: 39.5 | O8: 0 | P8: brainstorming:54 | Q8: Clarify:54 | S8: 0 | T8: 0 | U8: yes | V8: 622 | W8: 291
A9: 6FGzR0FFoIMiQ3y2otIsOqIyrMh2 | B9: -OwVMNSQxBd_hrnwU2xD | C9: Late Student Fears Teacher's Judgment | D9: 2026-07-02 09:07:08 | E9: 2026-07-02 09:27:54 | F9: brainstorming | G9: 10 | H9: 5 | I9: 5 | J9: 30 | K9: 182 | L9: 0.165 | M9: 6 | N9: 15.9 | O9: 0 | P9: brainstorming:8; deepthinking:2 | Q9: Clarify:8 | S9: 0 | T9: 0 | U9: yes | V9: 330 | W9: 30
A10: 6xMddtGgmcN42mZbnypoitgkFpa2 | B10: -OwWRBt8DVkudBkXs5c_ | C10: Junette's Thorned Garden of Pain | D10: 2026-07-02 14:07:47 | E10: 2026-07-02 14:12:31 | F10: brainstorming | G10: 33 | H10: 16 | I10: 17 | J10: 189 | K10: 501 | L10: 0.377 | M10: 11.8 | N10: 30.3 | O10: 0 | P10: brainstorming:30; deepthinking:3 | Q10: Clarify:30 | S10: 0 | T10: 0 | U10: yes | V10: 915 | W10: 189
A11: 7b2GdTbVRfUHAWpBDj4ZNTuE2UH2 | B11: -OwQlTUrDsKsjPp8eem_ | C11: Surviving Natural Disasters Together | D11: 2026-07-01 11:43:06 | E11: 2026-07-01 11:48:40 | F11: brainstorming | G11: 38 | H11: 19 | I11: 19 | J11: 125 | K11: 826 | L11: 0.151 | M11: 6.6 | N11: 31.2 | O11: 0 | P11: brainstorming:38 | Q11: Clarify:38 | S11: 0 | T11: 0 | U11: yes | V11: 463 | W11: 125
A12: 86IempJqjAe16ZnVEcfplb36dQK2 | B12: -OwVpU1B63hEDG7yjpwQ | C12: Alien Wolves Spread Cosmic Music | D12: 2026-07-02 11:18:40 | E12: 2026-07-02 11:46:45 | F12: brainstorming | G12: 22 | H12: 11 | I12: 11 | J12: 312 | K12: 475 | L12: 0.657 | M12: 28.4 | N12: 37.2 | O12: 0 | P12: brainstorming:22 | Q12: Clarify:22 | S12: 1 | T12: 0 | U12: yes | V12: 259 | W12: 312
A13: 8f8UOMJlUgXC014a2m6fBFiuUji1 | B13: -OwQ7dIytHxMgcyGrG5X | C13: Racist Wakes as Black Man | D13: 2026-07-01 08:44:45 | E13: 2026-07-01 08:57:28 | F13: brainstorming | G13: 28 | H13: 14 | I13: 14 | J13: 1104 | K13: 4745 | L13: 0.233 | M13: 78.9 | N13: 62.6 | O13: 0 | P13: brainstorming:28 | Q13: Clarify:28 | S13: 0 | T13: 0 | U13: yes | V13: 448 | W13: 1104
A14: 8ikpafQproYMb9YoPmwfJPens6O2 | B14: -OwQkyczI6UcKIXeUc2F | C14: You Got Lost: Field Trip Fear | D14: 2026-07-01 11:40:52 | E14: 2026-07-01 11:45:19 | F14: brainstorming | G14: 38 | H14: 19 | I14: 19 | J14: 195 | K14: 706 | L14: 0.276 | M14: 10.3 | N14: 31.8 | O14: 0 | P14: brainstorming:38 | Q14: Clarify:38 | S14: 0 | T14: 0 | U14: yes | V14: 131 | W14: 195
A15: AHeFHdwoiMWh94QkcWbW22EjkkO2 | B15: -OwVq8qgO1KoQeTL0uSH | C15: New Chat | D15: 2026-07-02 11:21:40 | E15: 2026-07-02 11:21:40 | F15: brainstorming | G15: 0 | H15: 0 | I15: 0 | J15: 0 | K15: 0 | O15: 0 | S15: 0 | T15: 0 | U15: no | V15: 0 | W15: 0
A16: B5ETbn4OQlbmR7jwyYjscFhyHMG2 | B16: -OwQ67133Lz-KNA9ZbdS | C16: Luxury Boat Murder Mystery | D16: 2026-07-01 08:38:04 | E16: 2026-07-01 08:44:50 | F16: brainstorming | G16: 32 | H16: 16 | I16: 16 | J16: 654 | K16: 3584 | L16: 0.182 | M16: 40.9 | N16: 72.9 | O16: 0 | P16: brainstorming:32 | Q16: Clarify:32 | S16: 0 | T16: 0 | U16: yes | V16: 485 | W16: 654
A17: BpdNWTiz1HPmyvrVdqlZIfyGpMO2 | B17: -OwVMPJUg7lZIxE8PYnt | C17: New Chat | D17: 2026-07-02 09:07:19 | E17: 2026-07-02 09:07:19 | F17: brainstorming | G17: 0 | H17: 0 | I17: 0 | J17: 0 | K17: 0 | O17: 0 | S17: 0 | T17: 0 | U17: yes | V17: 460 | W17: 0
A18: E8tQQtddL4Z8NvhbbqY8K5O4cfO2 | B18: -OwVqe2ZqcjWPBqat8LD | C18: New Chat | D18: 2026-07-02 11:23:45 | E18: 2026-07-02 11:23:45 | F18: brainstorming | G18: 4 | H18: 2 | I18: 2 | J18: 13 | K18: 86 | L18: 0.151 | M18: 6.5 | N18: 0.6 | O18: 0 | P18: deepthinking:4 | S18: 0 | T18: 0 | U18: yes | V18: 211 | W18: 13
A19: ENqphjWfdORTcp5Rm7ZI8lVt24g2 | B19: -OwVMVfcauohpncLoQI5 | C19: New Chat | D19: 2026-07-02 09:07:48 | E19: 2026-07-02 09:07:48 | F19: brainstorming | G19: 0 | H19: 0 | I19: 0 | J19: 0 | K19: 0 | O19: 0 | S19: 0 | T19: 0 | U19: no | V19: 0 | W19: 0
A20: FCANzDkmkYT1W6HgapUhdnZN0xo2 | B20: -OwQ6ALECCFlzb-y4I6x | C20: Bootylicious: Silent But Deadly | D20: 2026-07-01 08:38:13 | E20: 2026-07-01 08:54:42 | F20: brainstorming | G20: 12 | H20: 6 | I20: 6 | J20: 1017 | K20: 896 | L20: 1.135 | M20: 169.5 | N20: 77.9 | O20: 0 | P20: brainstorming:12 | Q20: Clarify:12 | S20: 0 | T20: 0 | U20: yes | V20: 795 | W20: 1017
A21: GC4oYcvlWFdKmK6Nkgi8i5hXCng1 | B21: -OwWaNAHSIHrqr86etjL | C21: New Chat | D21: 2026-07-02 14:52:14 | E21: 2026-07-02 14:52:14 | F21: deepthinking | G21: 0 | H21: 0 | I21: 0 | J21: 0 | K21: 0 | O21: 0 | S21: 0 | T21: 0 | U21: yes | V21: 553 | W21: 0
A22: JOXonotBYmMnqSLfh2NltHD8uXB2 | B22: -OwRJ-j-ilE_87Gj2nw- | C22: Survival Escape from the Forest | D22: 2026-07-01 14:13:57 | E22: 2026-07-01 14:16:14 | F22: brainstorming | G22: 90 | H22: 45 | I22: 45 | J22: 685 | K22: 2916 | L22: 0.235 | M22: 15.2 | N22: 37.7 | O22: 5 | P22: brainstorming:88; deepthinking:2 | Q22: Clarify:88 | S22: 0 | T22: 0 | U22: yes | V22: 448 | W22: 685
A23: JfiRrqZrDzOGZuUmcQ0xNNqqRPt2 | B23: -OwQ6l8yKXh0mxWfxDep | C23: Hometown Girl's Love and Safety | D23: 2026-07-01 08:40:51 | E23: 2026-07-01 08:51:18 | F23: brainstorming | G23: 28 | H23: 14 | I23: 14 | J23: 441 | K23: 2491 | L23: 0.177 | M23: 31.5 | N23: 81 | O23: 0 | P23: brainstorming:28 | Q23: Clarify:28 | S23: 0 | T23: 0 | U23: yes | V23: 385 | W23: 441
A24: Jr8NNAZgvmgiYpNb4K6qyiuo4tW2 | B24: -OwVLzRLoMyRpLu453uN | C24: The Ocean's Letters to a Sailor | D24: 2026-07-02 09:05:24 | E24: 2026-07-02 09:12:43 | F24: brainstorming | G24: 42 | H24: 21 | I24: 21 | J24: 672 | K24: 1273 | L24: 0.528 | M24: 32 | N24: 33.5 | O24: 0 | P24: brainstorming:28; deepthinking:14 | Q24: Clarify:28 | S24: 0 | T24: 0 | U24: yes | V24: 252 | W24: 672
A25: KSH5ttdNftVFL6Gd0J4yzvu2FBp1 | B25: -OwQlyLXRk2AjJhB_1XK | C25: Future Self's Warning Visit | D25: 2026-07-01 11:45:12 | E25: 2026-07-01 11:52:40 | F25: brainstorming | G25: 16 | H25: 8 | I25: 8 | J25: 81 | K25: 571 | L25: 0.142 | M25: 10.1 | N25: 10.7 | O25: 0 | P25: brainstorming:16 | Q25: Clarify:16 | S25: 0 | T25: 0 | U25: yes | V25: 171 | W25: 81
A26: KUrkPMRkNAhX9hnzS29LtPHaO5x2 | B26: -OwWRxGAtS_Mj2uTX05A | C26: Lost Museum School Trip Artifact | D26: 2026-07-02 14:11:06 | E26: 2026-07-02 14:23:02 | F26: brainstorming | G26: 10 | H26: 5 | I26: 5 | J26: 35 | K26: 295 | L26: 0.119 | M26: 7 | N26: 9.7 | O26: 0 | P26: brainstorming:10 | Q26: Clarify:10 | S26: 0 | T26: 0 | U26: yes | V26: 265 | W26: 35
A27: KgqLQajP4thdhVywhC6DGIFB1ZC3 | B27: -OwQ5iq5hA2tizYR68Jm | C27: User rejects shallow ideas | D27: 2026-07-01 08:36:17 | E27: 2026-07-01 08:39:34 | F27: brainstorming | G27: 42 | H27: 21 | I27: 21 | J27: 635 | K27: 3381 | L27: 0.188 | M27: 30.2 | N27: 73.4 | O27: 0 | P27: brainstorming:42 | Q27: Clarify:42 | S27: 0 | T27: 0 | U27: yes | V27: 1838 | W27: 635
A28: MElwPCsZEaaqKQAeCOXeM4qWdYu1 | B28: -OwQjT_gMvxUJOklGyTf | C28: AI Model Identity Query | D28: 2026-07-01 11:34:19 | E28: 2026-07-01 11:39:23 | F28: brainstorming | G28: 34 | H28: 17 | I28: 17 | J28: 112 | K28: 905 | L28: 0.124 | M28: 6.6 | N28: 10.6 | O28: 0 | P28: deepthinking:26; brainstorming:8 | Q28: Clarify:8 | S28: 0 | T28: 0 | U28: yes | V28: 487 | W28: 112
A29: OBnur9pwodNFSiYWQTQYk4j7H4o2 | B29: -OwQ5uPIXZNhYr-dE21- | C29: City Cafe Goodbye Romance | D29: 2026-07-01 08:37:04 | E29: 2026-07-01 08:42:08 | F29: brainstorming | G29: 54 | H29: 27 | I29: 27 | J29: 1043 | K29: 5630 | L29: 0.185 | M29: 38.6 | N29: 72.6 | O29: 0 | P29: brainstorming:54 | Q29: Clarify:54 | S29: 0 | T29: 0 | U29: yes | V29: 629 | W29: 1043
A30: Pi7fYOl6F9P8xIVy5Bp6Su1SJoi2 | B30: -OwQAnkWvNaVCgMtnfNd | C30: Dark Hero vs Chaos Villain | D30: 2026-07-01 08:58:35 | E30: 2026-07-01 09:03:24 | F30: brainstorming | G30: 12 | H30: 6 | I30: 6 | J30: 92 | K30: 1152 | L30: 0.08 | M30: 15.3 | N30: 5.6 | O30: 0 | P30: brainstorming:12 | Q30: Clarify:12 | S30: 0 | T30: 0 | U30: yes | V30: 554 | W30: 92
A31: Q0BdLRD5qMaXRnNKtRFXKHlCziC2 | B31: -OwVtA_ao_WTMq8bBTvq | C31: New Chat | D31: 2026-07-02 11:34:48 | E31: 2026-07-02 11:34:48 | F31: brainstorming | G31: 0 | H31: 0 | I31: 0 | J31: 0 | K31: 0 | O31: 0 | S31: 0 | T31: 0 | U31: yes | V31: 158 | W31: 0
A32: SVWibbwPvVNAPwJsXOWtvn3125r1 | B32: -OwWRMWABbsUTlM_nQei | C32: New Chat | D32: 2026-07-02 14:08:38 | E32: 2026-07-02 14:08:38 | F32: brainstorming | G32: 6 | H32: 3 | I32: 3 | J32: 19 | K32: 137 | L32: 0.139 | M32: 6.3 | N32: 5 | O32: 0 | P32: brainstorming:6 | Q32: Clarify:6 | S32: 0 | T32: 0 | U32: yes | V32: 446 | W32: 19
A33: SVWibbwPvVNAPwJsXOWtvn3125r1 | B33: -OwWScDTADV6U1kabyRw | C33: Joke Offends Classmate Essay Request | D33: 2026-07-02 14:14:09 | E33: 2026-07-02 14:17:15 | F33: brainstorming | G33: 28 | H33: 14 | I33: 14 | J33: 60 | K33: 1101 | L33: 0.054 | M33: 4.3 | N33: 11.3 | O33: 2 | P33: brainstorming:28 | Q33: Clarify:28 | S33: 0 | T33: 0 | U33: yes | V33: 446 | W33: 60
A34: SVWibbwPvVNAPwJsXOWtvn3125r1 | B34: -OwWVQuxmISXijxPEyRx | C34: Secret, Betrayal, and Quiet Repair | D34: 2026-07-02 14:26:25 | E34: 2026-07-02 14:31:46 | F34: brainstorming | G34: 16 | H34: 8 | I34: 8 | J34: 69 | K34: 901 | L34: 0.077 | M34: 8.6 | N34: 15.6 | O34: 0 | P34: brainstorming:16 | Q34: Clarify:16 | S34: 0 | T34: 0 | U34: yes | V34: 446 | W34: 69
A35: TQfxN5NKTYfrxWioKMzYuuiQ7qS2 | B35: -OwQt44-8tkBRRkCA2wN | C35: New Chat | D35: 2026-07-01 12:16:24 | E35: 2026-07-01 12:16:24 | F35: brainstorming | G35: 0 | H35: 0 | I35: 0 | J35: 0 | K35: 0 | O35: 0 | S35: 0 | T35: 0 | U35: no | V35: 0 | W35: 0
A36: UgthkQ3qazbkV3nqKoTewkGq1lG3 | B36: -OwVq20Wo7Gl4QKZo2Yn | C36: AI identity clarification request | D36: 2026-07-02 11:21:10 | E36: 2026-07-02 11:28:23 | F36: brainstorming | G36: 10 | H36: 5 | I36: 5 | J36: 13 | K36: 224 | L36: 0.058 | M36: 2.6 | N36: 5.3 | O36: 0 | P36: deepthinking:8; brainstorming:2 | Q36: Clarify:2 | S36: 0 | T36: 0 | U36: yes | V36: 206 | W36: 13
A37: UgthkQ3qazbkV3nqKoTewkGq1lG3 | B37: -OwVs0u1_ajLxzUOd35e | C37: Late Bus, Successful Presentation | D37: 2026-07-02 11:29:49 | E37: 2026-07-02 12:00:10 | F37: deepthinking | G37: 11 | H37: 5 | I37: 6 | J37: 217 | K37: 189 | L37: 1.148 | M37: 43.4 | N37: 29.9 | O37: 0 | P37: deepthinking:11 | S37: 0 | T37: 0 | U37: yes | V37: 206 | W37: 217
A38: VPYaFq2al4YL01itSYZZJWFuLyk2 | B38: -OwRIjberDi-Hqk417eW | C38: Ocean's Letter to a Sailor | D38: 2026-07-01 14:12:45 | E38: 2026-07-01 14:18:11 | F38: brainstorming | G38: 44 | H38: 22 | I38: 22 | J38: 741 | K38: 735 | L38: 1.008 | M38: 33.7 | N38: 39.7 | O38: 1 | P38: brainstorming:44 | Q38: Ideate:35; Clarify:9 | S38: 0 | T38: 0 | U38: yes | V38: 540 | W38: 741
A39: VeVNHm97tJMSOEMZA1zYMwT7kuv2 | B39: -OwRJYjygQFIHoTbiRvG | C39: Lost Alone in a Forest | D39: 2026-07-01 14:16:21 | E39: 2026-07-01 14:25:07 | F39: brainstorming | G39: 14 | H39: 7 | I39: 7 | J39: 60 | K39: 257 | L39: 0.233 | M39: 8.6 | N39: 7.9 | O39: 0 | P39: brainstorming:14 | Q39: Clarify:14 | S39: 0 | T39: 0 | U39: yes | V39: 333 | W39: 60
A40: WpheHrtzTNaussrzkoqf49fcuh42 | B40: -OwQkpEgdguEZXdk6Di- | C40: World Reacts to Talking Animal | D40: 2026-07-01 11:40:18 | E40: 2026-07-01 11:51:10 | F40: brainstorming | G40: 18 | H40: 9 | I40: 9 | J40: 46 | K40: 642 | L40: 0.072 | M40: 5.1 | N40: 13.5 | O40: 0 | P40: brainstorming:18 | Q40: Clarify:18 | S40: 0 | T40: 0 | U40: yes | V40: 275 | W40: 46
...

Sheet Turns
A1: uid | B1: session_id | C1: turn_index | D1: role | E1: mode | F1: stage | G1: timestamp | H1: word_count | I1: payload_kind | J1: visible_text | K1: raw_content_if_payload
A2: 0QaQYslhRSXNMdCEaDY35HzA2Xl2 | B2: -OwWRuDalQgU7vQhUj5g | C2: 0 | D2: student | E2: brainstorming | F2: Clarify | G2: 2026-07-02 14:12:49 | H2: 13 | J2: a girl is visiting her grandparent's creepy old house to collect their belongings
A3: 0QaQYslhRSXNMdCEaDY35HzA2Xl2 | B3: -OwWRuDalQgU7vQhUj5g | C3: 1 | D3: bot | E3: brainstorming | F3: Clarify | G3: 2026-07-02 14:12:57 | H3: 54 | J3: I love this premise! A quiet, personal task set against a creepy backdrop creates great tension. What draws you to this idea—is it the mystery of what she might find, or the emotional weight of saying goodbye? Let's frame it as an opportunity: How might we make the house itself feel like a character?
A4: 0QaQYslhRSXNMdCEaDY35HzA2Xl2 | B4: -OwWRuDalQgU7vQhUj5g | C4: 2 | D4: student | E4: brainstorming | F4: Clarify | G4: 2026-07-02 14:13:35 | H4: 7 | J4: the house is rusty and worn out
A5: 0QaQYslhRSXNMdCEaDY35HzA2Xl2 | B5: -OwWRuDalQgU7vQhUj5g | C5: 3 | D5: bot | E5: brainstorming | F5: Clarify | G5: 2026-07-02 14:13:41 | H5: 40 | J5: Exactly — the house already feels alive in its decay. That rawness could tell its own story. Let me reframe what you shared into another opportunity: How might we make the ordinary objects in the house feel unsettling or significant?
A6: 0QaQYslhRSXNMdCEaDY35HzA2Xl2 | B6: -OwWRuDalQgU7vQhUj5g | C6: 4 | D6: student | E6: brainstorming | F6: Clarify | G6: 2026-07-02 14:14:23 | H6: 3 | J6: im not sure
A7: 0QaQYslhRSXNMdCEaDY35HzA2Xl2 | B7: -OwWRuDalQgU7vQhUj5g | C7: 5 | D7: bot | E7: brainstorming | F7: Clarify | G7: 2026-07-02 14:14:31 | H7: 29 | J7: That's okay — uncertainty is part of the process. Let me try another angle. How might we use the act of collecting belongings to reveal a hidden family secret?
A8: 0QaQYslhRSXNMdCEaDY35HzA2Xl2 | B8: -OwWRuDalQgU7vQhUj5g | C8: 6 | D8: student | E8: brainstorming | F8: Clarify | G8: 2026-07-02 14:15:34 | H8: 14 | J8: while trying to find the belongings, she accidently finds something that she shouldnt have
A9: 0QaQYslhRSXNMdCEaDY35HzA2Xl2 | B9: -OwWRuDalQgU7vQhUj5g | C9: 7 | D9: bot | E9: brainstorming | F9: Clarify | G9: 2026-07-02 14:15:40 | H9: 31 | J9: That's a strong hook — the accidental discovery adds tension and stakes. Let me capture that as a question. How might we make the discovery feel inevitable yet shocking in hindsight?
A10: 0QaQYslhRSXNMdCEaDY35HzA2Xl2 | B10: -OwWRuDalQgU7vQhUj5g | C10: 8 | D10: student | E10: brainstorming | F10: Clarify | G10: 2026-07-02 14:16:29 | H10: 3 | J10: i dotn know
A11: 0QaQYslhRSXNMdCEaDY35HzA2Xl2 | B11: -OwWRuDalQgU7vQhUj5g | C11: 9 | D11: bot | E11: brainstorming | F11: Clarify | G11: 2026-07-02 14:16:36 | H11: 60 | J11: That's completely fine — sometimes the best ideas come from not knowing. Let me summarize what we have so far: A young girl visits her grandparents' rusty, worn-out house to collect their belongings, and accidentally finds something she shouldn't have. We've got three solid HMW questions. Let me check if we're ready to move into exploring variations — sound good?
A12: 0QaQYslhRSXNMdCEaDY35HzA2Xl2 | B12: -OwWRuDalQgU7vQhUj5g | C12: 10 | D12: student | E12: brainstorming | F12: Clarify | G12: 2026-07-02 14:16:56 | H12: 1 | J12: okay
A13: 0QaQYslhRSXNMdCEaDY35HzA2Xl2 | B13: -OwWRuDalQgU7vQhUj5g | C13: 11 | D13: bot | E13: brainstorming | F13: Clarify | G13: 2026-07-02 14:17:03 | H13: 25 | I13: full_json | J13: Great, let's start exploring! What if we SUBSTITUTE what she finds? Instead of a secret object, what if she finds a living person hiding there? | K13: <p>[ { "action": "switch_stage", "reasoning": "3 HMWs collected and base concept is clear (girl discovers something forbidden in grandparents' abandoned house). Ready to explore SCAMPER variations.", "data": { "toStage": "Ideate" } }, { "action": "respond", "reasoning": "Transition to ideation stage with substitute technique prompt", "data": { "message": "Great, let's start exploring! What if we SUBSTITUTE what she finds? Instead of a secret object, what if she finds a living person hiding there?" } } ]</p>
A14: 0QaQYslhRSXNMdCEaDY35HzA2Xl2 | B14: -OwWRuDalQgU7vQhUj5g | C14: 12 | D14: student | E14: brainstorming | F14: Clarify | G14: 2026-07-02 14:18:24 | H14: 13 | J14: what about a small animal that doesnt look like it came from earth
A15: 0QaQYslhRSXNMdCEaDY35HzA2Xl2 | B15: -OwWRuDalQgU7vQhUj5g | C15: 13 | D15: bot | E15: brainstorming | F15: Clarify | G15: 2026-07-02 14:18:32 | H15: 30 | I15: full_json | J15: That's a fascinating shift — alien creature in a dusty old house. What if we COMBINE that with a family secret? Maybe the grandparents were hiding this creature for years. | K15: <p>[ { "action": "log_idea", "reasoning": "User applies Substitute (what is found) - shifting from human secret to alien creature adds sci-fi/mystery element", "data": { "idea": "Instead of a forbidden secret, the girl finds a small, otherworldly animal hiding in the abandoned house.", "ideaId": null, "scamperTechnique": "Substitute", "evaluations": { "flexibilityCategory": "Plot", "elaboration": "Medium", "originality": "High", "reasoning": "Shifts genre from family drama to sci-fi mystery. The creature's origin and purpose become the central question." } } }, { "action": "respond", "reasoning": "Acknowledge the creative pivot and prompt for more detail", "data": { "message": "That's a fascinating shift — alien creature in a dusty old house. What if we COMBINE that with a family secret? Maybe the grandparents were hiding this creature for years." } } ]</p>
A16: 0QaQYslhRSXNMdCEaDY35HzA2Xl2 | B16: -OwWTu17Sxd9ROSqJ5t4 | C16: 0 | D16: student | E16: brainstorming | F16: Clarify | G16: 2026-07-02 14:21:07 | H16: 34 | J16: a girl is at her grandparent's old, rusty and worn out house to look for their belongings. while trying to find the belongings, she accidentally discovers a small animal that didnt come from earth
A17: 0QaQYslhRSXNMdCEaDY35HzA2Xl2 | B17: -OwWTu17Sxd9ROSqJ5t4 | C17: 1 | D17: bot | E17: brainstorming | F17: Clarify | G17: 2026-07-02 14:21:14 | H17: 50 | J17: That's a wonderful starting point—the contrast between the familiar, worn-out house and a completely alien creature is full of potential. To help frame this as a creative challenge: How might we make the discovery of the alien animal feel both magical and deeply personal, tied to the grandmother's hidden past?
A18: 0QaQYslhRSXNMdCEaDY35HzA2Xl2 | B18: -OwWTu17Sxd9ROSqJ5t4 | C18: 2 | D18: student | E18: brainstorming | F18: Clarify | G18: 2026-07-02 14:22:47 | H18: 14 | J18: her grandmother is actually a doppelganger and the real one had died long before
A19: 0QaQYslhRSXNMdCEaDY35HzA2Xl2 | B19: -OwWTu17Sxd9ROSqJ5t4 | C19: 3 | D19: bot | E19: brainstorming | F19: Clarify | G19: 2026-07-02 14:22:54 | H19: 46 | J19: That's a chilling revelation! So the alien animal might be connected to the doppelganger grandmother. Let me reframe that: How might we weave clues about the grandmother's true nature into the house itself, making the discovery of the alien animal the key that unlocks the mystery?
A20: 0QaQYslhRSXNMdCEaDY35HzA2Xl2 | B20: -OwWTu17Sxd9ROSqJ5t4 | C20: 4 | D20: student | E20: brainstorming | F20: Clarify | G20: 2026-07-02 14:25:23 | H20: 1 | J20: idk
A21: 0QaQYslhRSXNMdCEaDY35HzA2Xl2 | B21: -OwWTu17Sxd9ROSqJ5t4 | C21: 5 | D21: bot | E21: brainstorming | F21: Clarify | G21: 2026-07-02 14:25:29 | H21: 24 | J21: That's okay! Let's try another angle. How might we make the alien animal's reaction to the doppelganger grandmother reveal the truth to the girl?
A22: 0QaQYslhRSXNMdCEaDY35HzA2Xl2 | B22: -OwWTu17Sxd9ROSqJ5t4 | C22: 6 | D22: student | E22: brainstorming | F22: Clarify | G22: 2026-07-02 14:26:10 | H22: 12 | J22: the alien animal gets scared of the girl whos name is mia
A23: 0QaQYslhRSXNMdCEaDY35HzA2Xl2 | B23: -OwWTu17Sxd9ROSqJ5t4 | C23: 7 | D23: bot | E23: brainstorming | F23: Clarify | G23: 2026-07-02 14:26:17 | H23: 50 | J23: That's a beautiful, instinctive clue. So the animal knows something Mia doesn't yet—it senses the doppelganger's influence on her. Let me capture that as an opportunity question: How might we use the alien animal's fear of Mia to force her to question her own identity and connection to this house?
A24: 0QaQYslhRSXNMdCEaDY35HzA2Xl2 | B24: -OwWTu17Sxd9ROSqJ5t4 | C24: 8 | D24: student | E24: brainstorming | F24: Clarify | G24: 2026-07-02 14:29:54 | H24: 29 | J24: the animal runs under a bed when mia tries to approach it. mia then looked under the bed and finds a open trapdoor that the animal used to escape
A25: 0QaQYslhRSXNMdCEaDY35HzA2Xl2 | B25: -OwWTu17Sxd9ROSqJ5t4 | C25: 9 | D25: bot | E25: brainstorming | F25: Clarify | G25: 2026-07-02 14:30:00 | H25: 34 | J25: That's a great physical clue leading to discovery. Let me frame that: How might we design what's below the trapdoor to reveal both the grandmother's secret and the animal's origin at the same time?
A26: 0QaQYslhRSXNMdCEaDY35HzA2Xl2 | B26: -OwWTu17Sxd9ROSqJ5t4 | C26: 10 | D26: student | E26: brainstorming | F26: Clarify | G26: 2026-07-02 14:35:57 | H26: 9 | J26: change the alien like creature to a mini dragon
A27: 0QaQYslhRSXNMdCEaDY35HzA2Xl2 | B27: -OwWTu17Sxd9ROSqJ5t4 | C27: 11 | D27: bot | E27: brainstorming | F27: Clarify | G27: 2026-07-02 14:36:03 | H27: 40 | J27: That's a perfect substitution! A mini dragon feels more magical and personal for this story. Let me reframe as an opportunity: How might we make the mini dragon's presence in the house reveal clues about the doppelganger grandmother's true motives?
... A29: 0QaQYslhRSXNMdCEaDY35HzA2Xl2 | B29: -OwWTu17Sxd9ROSqJ5t4 | C29: 13 | D29: bot | E29: brainstorming | F29: Clarify | G29: 2026-07-02 14:36:33 | H29: 27 | J29: No worries. Let's try a different question. How might we make the mini dragon's reaction to the grandmother (fear? curiosity?) hint at who the real threat is?
A30: 0QaQYslhRSXNMdCEaDY35HzA2Xl2 | B30: -OwWTu17Sxd9ROSqJ5t4 | C30: 14 | D30: student | E30: deepthinking | G30: 2026-07-02 14:37:55 | H30: 1 | J30: idk
A31: 0QaQYslhRSXNMdCEaDY35HzA2Xl2 | B31: -OwWTu17Sxd9ROSqJ5t4 | C31: 15 | D31: bot | E31: deepthinking | G31: 2026-07-02 14:38:06 | H31: 44 | J31: I can see you're feeling stuck, and that's completely okay—sometimes stepping back and looking at the bigger picture helps. Let's shift gears a bit and think about what's driving your character forward. What is your character trying to achieve in this scene or storyline?
A32: 0QaQYslhRSXNMdCEaDY35HzA2Xl2 | B32: -OwWTu17Sxd9ROSqJ5t4 | C32: 16 | D32: student | E32: deepthinking | G32: 2026-07-02 14:38:52 | H32: 28 | J32: mia is now trying to find out why there is a hidden trapodoor under her grandma's bed and why there is a dragon living in hre house too
A33: 0QaQYslhRSXNMdCEaDY35HzA2Xl2 | B33: -OwWTu17Sxd9ROSqJ5t4 | C33: 17 | D33: bot | E33: deepthinking | G33: 2026-07-02 14:38:58 | H33: 31 | J33: Great! Now we have a clear goal for Mia. Let me check what we already know—have you established any details about the grandmother's past or her relationship with the house yet?
A34: 0QaQYslhRSXNMdCEaDY35HzA2Xl2 | B34: -OwWTu17Sxd9ROSqJ5t4 | C34: 18 | D34: student | E34: deepthinking | G34: 2026-07-02 14:39:13 | H34: 1 | J34: no
A35: 0QaQYslhRSXNMdCEaDY35HzA2Xl2 | B35: -OwWTu17Sxd9ROSqJ5t4 | C35: 19 | D35: bot | E35: deepthinking | G35: 2026-07-02 14:39:18 | H35: 35 | J35: Got it! No background yet for Grandma or the house. Let's ask a focused question to build some depth. What does Mia know about her grandmother's past that makes this discovery especially surprising or unsettling?
A36: 0QaQYslhRSXNMdCEaDY35HzA2Xl2 | B36: -OwWTu17Sxd9ROSqJ5t4 | C36: 20 | D36: student | E36: deepthinking | G36: 2026-07-02 14:40:49 | H36: 18 | J36: mia doesnt know much about her grandmother except the fact that she used to work as a scientist
A37: 0QaQYslhRSXNMdCEaDY35HzA2Xl2 | B37: -OwWTu17Sxd9ROSqJ5t4 | C37: 21 | D37: bot | E37: deepthinking | G37: 2026-07-02 14:40:55 | H37: 63 | J37: Excellent! That's a fantastic detail—a scientist grandmother opens up so many possibilities. It makes the trapdoor and the dragon feel less random and more like pieces of a larger puzzle connected to her work. Now that we have this key piece of information, should we save it to your story project? I can record Mia's goal and her grandmother's profession as a scientist.
A38: 0QaQYslhRSXNMdCEaDY35HzA2Xl2 | B38: -OwWTu17Sxd9ROSqJ5t4 | C38: 22 | D38: student | E38: deepthinking | G38: 2026-07-02 14:41:13 | H38: 1 | J38: okay
A39: 0QaQYslhRSXNMdCEaDY35HzA2Xl2 | B39: -OwWTu17Sxd9ROSqJ5t4 | C39: 23 | D39: bot | E39: deepthinking | G39: 2026-07-02 14:41:21 | H39: 54 | I39: inline_json | J39: I've created two characters for your story: Mia (the curious protagonist) and Grandma (the mysterious scientist). Now, let's go deeper— what kind of scientist was Grandma? Her specialty could unlock which secrets the trapdoor and dragon are connected to. For example: a biologist, a physicist, a cryptozoologist (someone who studies hidden animals like dragons)? | K39: <p><json> { "action": "stage_change", "reasoning": "User confirmed. Creating Mia as a character (Person node) and recording her goal (find out why grandma has a hidden trapdoor and a dragon). Also creating Grandma as a scientist character.", "data": { "requests": [ { "entityType": "node", "entityId": null, "newData": { "label": "Mia", "group": "Person", "attributes": { "goal": "uncover why her grandmother has a hidden trapdoor and a dragon", "knowledge": "knows little about grandma's past besides she was a scientist" } } }, { "entityType": "node", "entityId": null, "newData": { "label": "Grandma", "group": "Person", "attributes": { "profession": "scientist", "known_objects": "hidden trapdoor under bed, dragon living in house" } } } ] } } </json></p> <p>I've created two characters for your story: <strong>Mia</strong> (the curious protagonist) and <strong>Grandma</strong> (the mysterious scientist).</p> <p><strong>Now, let's go deeper—</strong> what kind of scientist was Grandma? Her specialty could unlock which secrets the trapdoor and dragon are connected to. For example: a biologist, a physicist, a cryptozoologist (someone who studies hidden animals like dragons)?</p>
A40: 0QaQYslhRSXNMdCEaDY35HzA2Xl2 | B40: -OwWTu17Sxd9ROSqJ5t4 | C40: 24 | D40: student | E40: deepthinking | G40: 2026-07-02 14:42:36 | H40: 21 | J40: uhm the real grandma died alrdy mia jus doesnt know that yet since there is a doppelganger acting like mia's grandma
A41: 0QaQYslhRSXNMdCEaDY35HzA2Xl2 | B41: -OwWTu17Sxd9ROSqJ5t4 | C41: 25 | D41: bot | E41: deepthinking | G41: 2026-07-02 14:42:45 | H41: 75 | I41: inline_json | J41: That's a brilliant twist! The doppelgänger adds so much tension. Let me update the records. Okay, now here's a question that digs into the mystery deeper: Since Mia doesn't know Grandma is an imposter, how has the doppelgänger been acting? Is the doppelgänger playing a warm, loving role to keep up appearances, or has Mia noticed small, strange behaviors that feel off about her grandmother? This could hint at how the truth might eventually unravel. | K41: <p>That's a brilliant twist! The doppelgänger adds so much tension. Let me update the records.</p> <p><json> { "action": "stage_change", "reasoning": "User revealed the real grandma is dead and a doppelgänger is impersonating her. Updating 'Grandma' node to reflect doppelgänger status, and confirming Mia's lack of knowledge.", "data": { "requests": [ { "entityType": "node", "entityId": null, "newData": { "label": "Grandma", "group": "Person", "attributes": { "profession": "scientist", "status": "deceased", "known_objects": "hidden trapdoor under bed, dragon living in house", "impersonator": "doppelgänger active", "real_grandma_identity": "unknown to Mia at this point" } } } ] } } </json></p> <p><strong>Okay, now here's a question that digs into the mystery deeper:</strong> Since Mia doesn't know Grandma is an imposter, how has the doppelgänger been acting? Is the doppelgänger playing a warm, loving role to keep up appearances, or has Mia noticed small, strange behaviors that feel off about her grandmother? This could hint at how the truth might eventually unravel.</p>
...

Sheet Ideas
A1: uid | B1: session_id | C1: turn_index | D1: timestamp | E1: mode | F1: stage | G1: idea | H1: scamper_technique | I1: flexibility_category | J1: originality_bot | K1: elaboration_bot | L1: bot_reasoning
A2: 0QaQYslhRSXNMdCEaDY35HzA2Xl2 | B2: -OwWRuDalQgU7vQhUj5g | C2: 13 | D2: 2026-07-02 14:18:32 | E2: brainstorming | F2: Clarify | G2: Instead of a forbidden secret, the girl finds a small, otherworldly animal hiding in the abandoned house. | H2: Substitute | I2: Plot | J2: High | K2: Medium | L2: Shifts genre from family drama to sci-fi mystery. The creature's origin and purpose become the central question.
A3: 3w9E9Xr7oehGE2ThwcIxvybuKwE2 | B3: -OwVprk7ZBkimJoUaB_0 | C3: 17 | D3: 2026-07-02 11:27:46 | E3: brainstorming | F3: Clarify | G3: Dog has a strong prey drive, repeatedly sidetracked by chasing cats and birds, causing comedic detours from its main journey | H3: Modify | I3: Character | J3: Medium | K3: Medium | L3: Refines dog's core personality trait into a narrative engine for comedy and obstacles
A4: 3w9E9Xr7oehGE2ThwcIxvybuKwE2 | B4: -OwVprk7ZBkimJoUaB_0 | C4: 19 | D4: 2026-07-02 11:28:20 | E4: brainstorming | F4: Clarify | G4: Eliminate all human viewpoints and dialogue. The story is told entirely through the dog's sensory experiences and canine logic | H4: Eliminate | I4: Mechanic | J4: High | K4: Medium | L4: Pure sensory narration is uncommon and challenging, raising originality

Sheet Bot_Actions
A1: uid | B1: session_id | C1: turn_index | D1: timestamp | E1: mode | F1: stage | G1: action | H1: reasoning | I1: data_json
A2: 0QaQYslhRSXNMdCEaDY35HzA2Xl2 | B2: -OwWRuDalQgU7vQhUj5g | C2: 11 | D2: 2026-07-02 14:17:03 | E2: brainstorming | F2: Clarify | G2: switch_stage | H2: 3 HMWs collected and base concept is clear (girl discovers something forbidden in grandparents' abandoned house). Ready to explore SCAMPER variations. | I2: {"toStage": "Ideate"}
A3: 0QaQYslhRSXNMdCEaDY35HzA2Xl2 | B3: -OwWTu17Sxd9ROSqJ5t4 | C3: 23 | D3: 2026-07-02 14:41:21 | E3: deepthinking | G3: stage_change | H3: User confirmed. Creating Mia as a character (Person node) and recording her goal (find out why grandma has a hidden trapdoor and a dragon). Also creating Grandma as a scientist character. | I3: {"requests": [{"entityType": "node", "entityId": null, "newData": {"label": "Mia", "group": "Person", "attributes": {"goal": "uncover why her grandmother has a hidden trapdoor and a dragon", "knowledge": "knows little about grandma's past besides she was a scientist"}}}, {"entityType": "node", "entityId": null, "newData": {"label": "Grandma", "group": "Person", "attributes": {"profession": "scientist", "known_objects": "hidden trapdoor under bed, dragon living in house"}}}]}
A4: 0QaQYslhRSXNMdCEaDY35HzA2Xl2 | B4: -OwWTu17Sxd9ROSqJ5t4 | C4: 25 | D4: 2026-07-02 14:42:45 | E4: deepthinking | G4: stage_change | H4: User revealed the real grandma is dead and a doppelgänger is impersonating her. Updating 'Grandma' node to reflect doppelgänger status, and confirming Mia's lack of knowledge. | I4: {"requests": [{"entityType": "node", "entityId": null, "newData": {"label": "Grandma", "group": "Person", "attributes": {"profession": "scientist", "status": "deceased", "known_objects": "hidden trapdoor under bed, dragon living in house", "impersonator": "doppelgänger active", "real_grandma_identity": "unknown to Mia at this point"}}}]}
A5: rJTIkz4BJUftHE5g5pil8THAMQL2 | B5: -OwRJZuWNFKZ0OZSAwXR | C5: 17 | D5: 2026-07-01 14:26:35 | E5: brainstorming | F5: Clarify | G5: add_hmw | H5: Framing the user's idea about disbelief and time pressure as a focused creative challenge | I5: {"hmwQuestion": "How might we show the passing of time and mounting pressure while people refuse to believe the character's warning?"}
A6: rJTIkz4BJUftHE5g5pil8THAMQL2 | B6: -OwRJZuWNFKZ0OZSAwXR | C6: 21 | D6: 2026-07-01 14:29:38 | E6: brainstorming | F6: Clarify | G6: add_hmw | H6: Framing the user's question about continuation as a creative challenge about maintaining tension after the reveal | I6: {"hmwQuestion": "How might we sustain narrative drive after the protagonist is proven right about the storm?"}
A7: rJTIkz4BJUftHE5g5pil8THAMQL2 | B7: -OwRJZuWNFKZ0OZSAwXR | C7: 23 | D7: 2026-07-01 14:30:36 | E7: brainstorming | F7: Clarify | G7: add_hmw | H7: The user wants the storm to arrive as a consequence, framing this as a narrative opportunity about delayed action | I7: {"hmwQuestion": "How might we make the storm's arrival feel both inevitable and devastating, rewarding the protagonist's foresight with tragedy?"}
A8: rJTIkz4BJUftHE5g5pil8THAMQL2 | B8: -OwRJZuWNFKZ0OZSAwXR | C8: 23 | D8: 2026-07-01 14:30:36 | E8: brainstorming | F8: Clarify | G8: check_progress | H8: Checking if backend confirms readiness to advance to Ideate stage | I8: {}

Sheet Stories
A1: uid | B1: in_window | C1: n_sessions_in_window | D1: n_stories | E1: n_parts | F1: n_drafts | G1: drafts_per_part | H1: essay_words | I1: first_write | J1: last_write | K1: writing_span_min | L1: has_graph | M1: has_timeline | N1: summary | O1: essay_text
